# 迭代语句

## while语句

只要条件为真，while语句就重复的执行循环体，它的语法形式时
```cpp
    while (condition)
        statement
```

## 传统for语句

for(;;)

## 范围for语句

```cpp
    for (declaration:expression)
        statement
```

* expression表示的必须是一个序列
* declaration定义一个变量，序列中的每个元素都能转换成该变量的类型。确保类型相容最简单的办法是使用auto类型说明符

## do while 语句

# 跳转语句

## break语句

* break语句（break statement）负责终止离它最近的while、do while、 for或switch语句，并从这些语句之后的第一条语句开始继续执行
* break语句只能出现在迭代语句或switch语句内部

## continue语句

* continue语句 终止最近的循环中的当前迭代并立即开始下一次迭代。continue语句只能出现在for、while、do while循环的内部

## goto 语句

形式：
```cpp
    //..
    goto end; //将跳过下一行
    int ix = 10;
end:
    int ix = 42;
```

# try 语句块和异常处理

 异常是值存在于运行时的反常行为，这些行为超出了函数正常功能的范围。典型的异常包括失去数据库连接以及遇到意外输入等。处理反常行为可能是设计所有系统最难的一部分
 异常处理机制为程序中异常检测和异常处理这两部分的协作提供支持。在C++语言中，异常处理包括：
 * `throw表达式`(throw expression),异常检测部分使用throw表达式来表示它遇到了无法处理的问题。我们说throw引发（rasie）了异常
 * `try语句块`(try block),异常处理部分使用try语句块处理异常。try语句快以关键字try开始，并以一个或多个`catch子句（catch clause）`结束。try语句块中代码抛出的异常通常会倍某个catch子句处理。因为catch子句"处理"异常，所以他们也被称作**异常处理代码**
 * 一套**异常类（exception class）**,用于在throw表达式和相关的catch子句之间传递异常的具体信息

# throw表达式

程序的异常检测部分使用throw表达式引发一个异常。throw表达式包含关键字throw和紧随其后的一个表达式，其中表达式的类型就是抛出的异常类型。throw表达式后面通常紧跟一个分号，从而构成一条表达式语句。

以（书中第20页）把两个Sales_items对象相加的程序为例。这个程序检查它读入的记录是否是关于同一种书籍的，如果不是，输出一条信息然后退出。
```cpp
    Sales_item item1, item2;
    cin >> item1 >> item2;
    // 首先检查item1和item2是否表示同一种书籍
    if（item1.isbn() == item2.isbn）
    {
        cout << item1 + item2 <<endl;
        return 0;//表示成功
    }
    else
    {
        cerr << "Data must refer to same ISBN" << endl;
        return -1; //表示失败
    }
```
在真实的程序中，应该把对象相加的代码和用户交互的代码分离开来。此例中，我们改写程序使得检查完成后不在直接输出一条信息，而是抛出一个异常：
```cpp
    // 首先检查两条数据是否是关于同一种书籍的
    if (item1.isbn() != item2.isbn())
        throw runtime_error("Data must refer to same ISBN")；
    // 如果程序执行到了这里，表示两个ISBN是相同的
    cout << item1 + item2 << endl;
```
在这段代码中，如果ISBN不一样就抛出一个异常，该异常是类型runtime_error的对象。抛出异常将终止当前的函数，并把控制权转移给能处理该异常的代码。
类型runtime_error是标准库异常类型中的一种，定义在stdexcept头文件中。后续将了解更多标准库异常类型。我们必须初始化runtime_error的对象，方式是给它提供一个string对象或者一个C风格的字符串，这个字符串中有一些关于异常的辅助信息

# try语句块

try 语句块的通用语法形式是
```cpp
    try {
        program-statements
    } catch (exception-declaration) {
        handlers-statements
    } catch (exception- declaration) {
        handlers-statements
    } // ...
```
try 语句块的一开始是关键字try，随后紧跟着一个块，这个块就像大多数时候那样是花括号括起来的语句序列。
跟在try块之后的是一个或多个catch子句。catch子句包含三个部分：关键字catch、括号内一个（可能未命名的）对象的声明（称作异常声明，exception declaration）以及一个块。当选中了某个catch子句处理异常之后，执行与之对应的块。catch一旦完成，程序跳转到try语句块最后一个catch子句之后的那条语句继续执行。
try 语句块中的program-statements组成程序的正常逻辑，向其他任何块一样，program-statements可以有包括声明在内的任意C++语句。一如往常，try语句块内声明的变量在块外部无法访问，特别是在catch子句内也无法访问。

## 编写处理代码

仍然以两个Sales_item相加为例
```cpp
    while (cin >> item1 >> item2)
    {
        try {
            //执行添加两个Sales_item对象的代码
            //如果添加失败，代码抛出一个runtime_error异常
        } catch (runtime_error err)
        {
            // 提醒用户两个ISBN必须一致，询问是否重新输入
            cout << err.what() << "\nTry Again? Enter y or n"<< endl;
            char c;
            cin >> c;
            if (!cin || c == 'n')
                break; // 跳出while循环
        }
    }
```
程序本来要执行的任务出现在try语句块中，这是因为这段代码可能会抛出一个runtime_error类型的异常。


## 标准异常

C++标准库定义了一组类，用于报告标准库函数遇到的问题。这些异常类也可以在用户编写的程序中使用，他们分别定义在4个头文件中
* exception头文件定义了最通用的异常类exception。它只报告异常的发生，不提供任何额外信息
* stdexcept头文件定义了几张常用的异常类，详细信息在下列出
* new头文件定义了bad_alloc异常累心，这种类型在12章讲
* type_info头文件定义了bad_cast异常类型，在18章详细介绍

`<>stdexcept>`定义的异常类：  
|--- |---|  
| exception | 最常见的问题|  
| runtime_error | 只有在运行时才能检测出的问题|  
| range_error   | 运行时错误：生成的结果超出了有意义的值域范围|  
| overflow_error | 运行时错误：计算上溢|  
| underflow_error | 运行时错误：计算下溢|  
| logic_error | 程序逻辑错误|  
| domain_error | 逻辑错误：参数对应的结果值不存在| 
| incalid_argument | 逻辑错误：无效参数 |  
| length_error| 逻辑错误：视图创建一个超出该类型最大长度的对象|  
| out_of_range | 逻辑错误：使用一个超过有效范围的值|  
